Failure # 1 (occurred at 2022-09-21_15-24-18)
Traceback (most recent call last):
  File "C:\Users\Aplissonneau\AppData\Local\Continuum\anaconda3\envs\multitask\lib\site-packages\ray\tune\ray_trial_executor.py", line 901, in get_next_executor_event
    future_result = ray.get(ready_future)
  File "C:\Users\Aplissonneau\AppData\Local\Continuum\anaconda3\envs\multitask\lib\site-packages\ray\_private\client_mode_hook.py", line 105, in wrapper
    return func(*args, **kwargs)
  File "C:\Users\Aplissonneau\AppData\Local\Continuum\anaconda3\envs\multitask\lib\site-packages\ray\worker.py", line 1811, in get
    raise value
ray.exceptions.RayActorError: The actor died because of an error raised in its creation task, [36mray::ApexTrainer.__init__()[39m (pid=20092, ip=127.0.0.1, repr=ApexTrainer)
  File "C:\Users\Aplissonneau\AppData\Local\Continuum\anaconda3\envs\multitask\lib\site-packages\ray\util\tracing\tracing_helper.py", line 462, in _resume_span
    return method(self, *_args, **_kwargs)
  File "C:\Users\Aplissonneau\AppData\Local\Continuum\anaconda3\envs\multitask\lib\site-packages\ray\rllib\agents\trainer.py", line 1035, in _init
    raise NotImplementedError
NotImplementedError

During handling of the above exception, another exception occurred:

[36mray::ApexTrainer.__init__()[39m (pid=20092, ip=127.0.0.1, repr=ApexTrainer)
  File "python\ray\_raylet.pyx", line 656, in ray._raylet.execute_task
  File "python\ray\_raylet.pyx", line 697, in ray._raylet.execute_task
  File "python\ray\_raylet.pyx", line 663, in ray._raylet.execute_task
  File "python\ray\_raylet.pyx", line 667, in ray._raylet.execute_task
  File "python\ray\_raylet.pyx", line 614, in ray._raylet.execute_task.function_executor
  File "C:\Users\Aplissonneau\AppData\Local\Continuum\anaconda3\envs\multitask\lib\site-packages\ray\_private\function_manager.py", line 701, in actor_method_executor
    return method(__ray_actor, *args, **kwargs)
  File "C:\Users\Aplissonneau\AppData\Local\Continuum\anaconda3\envs\multitask\lib\site-packages\ray\util\tracing\tracing_helper.py", line 462, in _resume_span
    return method(self, *_args, **_kwargs)
  File "C:\Users\Aplissonneau\AppData\Local\Continuum\anaconda3\envs\multitask\lib\site-packages\ray\rllib\agents\trainer.py", line 831, in __init__
    config, logger_creator, remote_checkpoint_dir, sync_function_tpl
  File "C:\Users\Aplissonneau\AppData\Local\Continuum\anaconda3\envs\multitask\lib\site-packages\ray\tune\trainable.py", line 149, in __init__
    self.setup(copy.deepcopy(self.config))
  File "C:\Users\Aplissonneau\AppData\Local\Continuum\anaconda3\envs\multitask\lib\site-packages\ray\util\tracing\tracing_helper.py", line 462, in _resume_span
    return method(self, *_args, **_kwargs)
  File "C:\Users\Aplissonneau\AppData\Local\Continuum\anaconda3\envs\multitask\lib\site-packages\ray\rllib\agents\trainer.py", line 933, in setup
    self.workers, self.config, **self._kwargs_for_execution_plan()
  File "C:\Users\Aplissonneau\AppData\Local\Continuum\anaconda3\envs\multitask\lib\site-packages\ray\rllib\agents\dqn\apex.py", line 174, in execution_plan
    node=platform.node(),  # localhost
  File "C:\Users\Aplissonneau\AppData\Local\Continuum\anaconda3\envs\multitask\lib\site-packages\ray\rllib\utils\actors.py", line 121, in create_colocated_actors
    node=node,
  File "C:\Users\Aplissonneau\AppData\Local\Continuum\anaconda3\envs\multitask\lib\site-packages\ray\rllib\utils\actors.py", line 185, in try_create_colocated
    co_located, non_co_located = split_colocated(actors, node=node)
  File "C:\Users\Aplissonneau\AppData\Local\Continuum\anaconda3\envs\multitask\lib\site-packages\ray\rllib\utils\actors.py", line 220, in split_colocated
    hosts = ray.get([a.get_host.remote() for a in actors])
  File "C:\Users\Aplissonneau\AppData\Local\Continuum\anaconda3\envs\multitask\lib\site-packages\ray\_private\client_mode_hook.py", line 105, in wrapper
    return func(*args, **kwargs)
  File "C:\Users\Aplissonneau\AppData\Local\Continuum\anaconda3\envs\multitask\lib\site-packages\ray\worker.py", line 1811, in get
    raise value
ray.exceptions.RayActorError: The actor died because of an error raised in its creation task, [36mray::MultiAgentReplayBuffer.__init__()[39m (pid=20652, ip=127.0.0.1, repr=<ray.rllib.execution.buffers.multi_agent_replay_buffer.FunctionActorManager._create_fake_actor_class.<locals>.TemporaryActor object at 0x000001ADF9C88708>)
  File "python\ray\_raylet.pyx", line 663, in ray._raylet.execute_task
  File "python\ray\_raylet.pyx", line 667, in ray._raylet.execute_task
  File "python\ray\_raylet.pyx", line 614, in ray._raylet.execute_task.function_executor
  File "C:\Users\Aplissonneau\AppData\Local\Continuum\anaconda3\envs\multitask\lib\site-packages\ray\_private\function_manager.py", line 701, in actor_method_executor
    return method(__ray_actor, *args, **kwargs)
  File "C:\Users\Aplissonneau\AppData\Local\Continuum\anaconda3\envs\multitask\lib\site-packages\ray\_private\function_manager.py", line 595, in temporary_actor_method
    f"The actor with name {actor_class_name} "
RuntimeError: The actor with name MultiAgentReplayBuffer failed to import on the worker. This may be because needed library dependencies are not installed in the worker environment:

[36mray::MultiAgentReplayBuffer.__init__()[39m (pid=20652, ip=127.0.0.1, repr=<ray.rllib.execution.buffers.multi_agent_replay_buffer.FunctionActorManager._create_fake_actor_class.<locals>.TemporaryActor object at 0x000001ADF9C88708>)
  File "C:\Users\Aplissonneau\AppData\Local\Continuum\anaconda3\envs\multitask\lib\site-packages\ray\_private\function_manager.py", line 654, in _load_actor_class_from_gcs
    actor_class = pickle.loads(pickled_class)
  File "C:\Users\Aplissonneau\AppData\Local\Continuum\anaconda3\envs\multitask\lib\site-packages\ray\rllib\__init__.py", line 5, in <module>
    from ray.rllib.env.base_env import BaseEnv
  File "C:\Users\Aplissonneau\AppData\Local\Continuum\anaconda3\envs\multitask\lib\site-packages\ray\rllib\env\__init__.py", line 1, in <module>
    from ray.rllib.env.base_env import BaseEnv
  File "C:\Users\Aplissonneau\AppData\Local\Continuum\anaconda3\envs\multitask\lib\site-packages\ray\rllib\env\base_env.py", line 6, in <module>
    from ray.rllib.utils.annotations import Deprecated, override, PublicAPI
  File "C:\Users\Aplissonneau\AppData\Local\Continuum\anaconda3\envs\multitask\lib\site-packages\ray\rllib\utils\__init__.py", line 8, in <module>
    from ray.rllib.utils.filter import Filter
  File "C:\Users\Aplissonneau\AppData\Local\Continuum\anaconda3\envs\multitask\lib\site-packages\ray\rllib\utils\filter.py", line 6, in <module>
    from ray.rllib.utils.numpy import SMALL_NUMBER
  File "C:\Users\Aplissonneau\AppData\Local\Continuum\anaconda3\envs\multitask\lib\site-packages\ray\rllib\utils\numpy.py", line 11, in <module>
    torch, _ = try_import_torch()
  File "C:\Users\Aplissonneau\AppData\Local\Continuum\anaconda3\envs\multitask\lib\site-packages\ray\rllib\utils\framework.py", line 181, in try_import_torch
    import torch
  File "C:\Users\Aplissonneau\AppData\Local\Continuum\anaconda3\envs\multitask\lib\site-packages\torch\__init__.py", line 123, in <module>
    raise err
OSError: [WinError 1455] Le fichier de pagination est insuffisant pour terminer cette opération. Error loading "C:\Users\Aplissonneau\AppData\Local\Continuum\anaconda3\envs\multitask\lib\site-packages\torch\lib\caffe2_detectron_ops_gpu.dll" or one of its dependencies.

