Failure # 1 (occurred at 2022-09-21_15-27-53)
Traceback (most recent call last):
  File "C:\Users\Aplissonneau\AppData\Local\Continuum\anaconda3\envs\multitask\lib\site-packages\ray\tune\ray_trial_executor.py", line 901, in get_next_executor_event
    future_result = ray.get(ready_future)
  File "C:\Users\Aplissonneau\AppData\Local\Continuum\anaconda3\envs\multitask\lib\site-packages\ray\_private\client_mode_hook.py", line 105, in wrapper
    return func(*args, **kwargs)
  File "C:\Users\Aplissonneau\AppData\Local\Continuum\anaconda3\envs\multitask\lib\site-packages\ray\worker.py", line 1809, in get
    raise value.as_instanceof_cause()
ray.exceptions.RayTaskError(RayOutOfMemoryError): [36mray::ApexTrainer.train()[39m (pid=20540, ip=127.0.0.1, repr=ApexTrainer)
  File "python\ray\_raylet.pyx", line 663, in ray._raylet.execute_task
  File "python\ray\_raylet.pyx", line 667, in ray._raylet.execute_task
  File "python\ray\_raylet.pyx", line 614, in ray._raylet.execute_task.function_executor
  File "C:\Users\Aplissonneau\AppData\Local\Continuum\anaconda3\envs\multitask\lib\site-packages\ray\_private\function_manager.py", line 701, in actor_method_executor
    return method(__ray_actor, *args, **kwargs)
  File "C:\Users\Aplissonneau\AppData\Local\Continuum\anaconda3\envs\multitask\lib\site-packages\ray\util\tracing\tracing_helper.py", line 462, in _resume_span
    return method(self, *_args, **_kwargs)
  File "C:\Users\Aplissonneau\AppData\Local\Continuum\anaconda3\envs\multitask\lib\site-packages\ray\tune\trainable.py", line 349, in train
    result = self.step()
  File "C:\Users\Aplissonneau\AppData\Local\Continuum\anaconda3\envs\multitask\lib\site-packages\ray\util\tracing\tracing_helper.py", line 462, in _resume_span
    return method(self, *_args, **_kwargs)
  File "C:\Users\Aplissonneau\AppData\Local\Continuum\anaconda3\envs\multitask\lib\site-packages\ray\rllib\agents\trainer.py", line 1088, in step
    raise e
  File "C:\Users\Aplissonneau\AppData\Local\Continuum\anaconda3\envs\multitask\lib\site-packages\ray\rllib\agents\trainer.py", line 1074, in step
    step_attempt_results = self.step_attempt()
  File "C:\Users\Aplissonneau\AppData\Local\Continuum\anaconda3\envs\multitask\lib\site-packages\ray\util\tracing\tracing_helper.py", line 462, in _resume_span
    return method(self, *_args, **_kwargs)
  File "C:\Users\Aplissonneau\AppData\Local\Continuum\anaconda3\envs\multitask\lib\site-packages\ray\rllib\agents\trainer.py", line 1155, in step_attempt
    step_results = self._exec_plan_or_training_iteration_fn()
  File "C:\Users\Aplissonneau\AppData\Local\Continuum\anaconda3\envs\multitask\lib\site-packages\ray\util\tracing\tracing_helper.py", line 462, in _resume_span
    return method(self, *_args, **_kwargs)
  File "C:\Users\Aplissonneau\AppData\Local\Continuum\anaconda3\envs\multitask\lib\site-packages\ray\rllib\agents\trainer.py", line 2174, in _exec_plan_or_training_iteration_fn
    results = next(self.train_exec_impl)
  File "C:\Users\Aplissonneau\AppData\Local\Continuum\anaconda3\envs\multitask\lib\site-packages\ray\util\iter.py", line 779, in __next__
    return next(self.built_iterator)
  File "C:\Users\Aplissonneau\AppData\Local\Continuum\anaconda3\envs\multitask\lib\site-packages\ray\util\iter.py", line 807, in apply_foreach
    for item in it:
  File "C:\Users\Aplissonneau\AppData\Local\Continuum\anaconda3\envs\multitask\lib\site-packages\ray\util\iter.py", line 807, in apply_foreach
    for item in it:
  File "C:\Users\Aplissonneau\AppData\Local\Continuum\anaconda3\envs\multitask\lib\site-packages\ray\util\iter.py", line 869, in apply_filter
    for item in it:
  File "C:\Users\Aplissonneau\AppData\Local\Continuum\anaconda3\envs\multitask\lib\site-packages\ray\util\iter.py", line 869, in apply_filter
    for item in it:
  File "C:\Users\Aplissonneau\AppData\Local\Continuum\anaconda3\envs\multitask\lib\site-packages\ray\util\iter.py", line 807, in apply_foreach
    for item in it:
  File "C:\Users\Aplissonneau\AppData\Local\Continuum\anaconda3\envs\multitask\lib\site-packages\ray\util\iter.py", line 869, in apply_filter
    for item in it:
  File "C:\Users\Aplissonneau\AppData\Local\Continuum\anaconda3\envs\multitask\lib\site-packages\ray\util\iter.py", line 1108, in build_union
    item = next(it)
  File "C:\Users\Aplissonneau\AppData\Local\Continuum\anaconda3\envs\multitask\lib\site-packages\ray\util\iter.py", line 779, in __next__
    return next(self.built_iterator)
  File "C:\Users\Aplissonneau\AppData\Local\Continuum\anaconda3\envs\multitask\lib\site-packages\ray\util\iter.py", line 807, in apply_foreach
    for item in it:
  File "C:\Users\Aplissonneau\AppData\Local\Continuum\anaconda3\envs\multitask\lib\site-packages\ray\util\iter.py", line 807, in apply_foreach
    for item in it:
  File "C:\Users\Aplissonneau\AppData\Local\Continuum\anaconda3\envs\multitask\lib\site-packages\ray\util\iter.py", line 807, in apply_foreach
    for item in it:
  [Previous line repeated 1 more time]
  File "C:\Users\Aplissonneau\AppData\Local\Continuum\anaconda3\envs\multitask\lib\site-packages\ray\util\iter.py", line 869, in apply_filter
    for item in it:
  File "C:\Users\Aplissonneau\AppData\Local\Continuum\anaconda3\envs\multitask\lib\site-packages\ray\util\iter.py", line 572, in base_iterator
    batch = ray.get(obj_ref)
  File "C:\Users\Aplissonneau\AppData\Local\Continuum\anaconda3\envs\multitask\lib\site-packages\ray\_private\client_mode_hook.py", line 105, in wrapper
    return func(*args, **kwargs)
  File "C:\Users\Aplissonneau\AppData\Local\Continuum\anaconda3\envs\multitask\lib\site-packages\ray\worker.py", line 1809, in get
    raise value.as_instanceof_cause()
ray.exceptions.RayTaskError(RayOutOfMemoryError): [36mray::MultiAgentReplayBuffer.par_iter_next_batch()[39m (pid=21068, ip=127.0.0.1, repr=<ray.rllib.execution.buffers.multi_agent_replay_buffer.MultiAgentReplayBuffer object at 0x0000017F5FF29D48>)
  File "python\ray\_raylet.pyx", line 621, in ray._raylet.execute_task
  File "C:\Users\Aplissonneau\AppData\Local\Continuum\anaconda3\envs\multitask\lib\site-packages\ray\_private\memory_monitor.py", line 164, in raise_if_low_memory
    used_gb, total_gb, self.error_threshold
ray._private.memory_monitor.RayOutOfMemoryError: More than 95% of the memory on node PC-Plissonneau is used (15.02 / 15.79 GB). The top 10 memory consumers are:

PID	MEM	COMMAND
20540	3.36GiB	C:\Users\Aplissonneau\AppData\Local\Continuum\anaconda3\envs\multitask\python.exe C:\Users\Aplissonn
15892	0.56GiB	C:\Users\Aplissonneau\AppData\Local\Continuum\anaconda3\envs\multitask\python.exe C:\Users\Aplissonn
8912	0.48GiB	C:\Users\Aplissonneau\AppData\Local\Continuum\anaconda3\envs\multitask\python.exe C:\Users\Aplissonn
4052	0.48GiB	C:\Users\Aplissonneau\AppData\Local\Continuum\anaconda3\envs\multitask\python.exe C:\Users\Aplissonn
21068	0.48GiB	C:\Users\Aplissonneau\AppData\Local\Continuum\anaconda3\envs\multitask\python.exe C:\Users\Aplissonn
19624	0.48GiB	C:\Users\Aplissonneau\AppData\Local\Continuum\anaconda3\envs\multitask\python.exe C:\Users\Aplissonn
16640	0.41GiB	python training_ray.py
15328	0.34GiB	C:\Users\Aplissonneau\AppData\Local\Microsoft\Teams\current\Teams.exe --type=renderer --autoplay-pol
15344	0.33GiB	C:\Program Files\Microsoft Office\root\Office16\OUTLOOK.EXE
8564	0.28GiB	C:\Users\Aplissonneau\AppData\Local\Continuum\anaconda3\envs\multitask\pythonw.exe C:\Users\Aplisson

In addition, up to 0.0 GiB of shared memory is currently being used by the Ray object store.
---
--- Tip: Use the `ray memory` command to list active objects in the cluster.
--- To disable OOM exceptions, set RAY_DISABLE_MEMORY_MONITOR=1.
---

